/*
 * Neo JavaScript Engine Test Suite
 * Copyright (c) 2025 Ata Türkçü. All rights reserved.
 * Licensed under the BSD-3-Clause License
 *
 * Test: Advanced Try-Catch-Finally Scenarios
 * Complex error handling, nested blocks, exception propagation,
 * finally block edge cases, and resource cleanup patterns
 */

// Test complex nested try-catch-finally with multiple exception paths
var complexNestingTest = function() {
    var results = [];
    var outerFinally = false;
    var innerFinally = false;
    var catchExecuted = false;

    try {
        try {
            try {
                results.push("innermost-try");
                throw new Error("innermost error");
            } catch (e) {
                results.push("innermost-catch");
                throw new TypeError("rethrown as TypeError");
            } finally {
                results.push("innermost-finally");
                innerFinally = true;
            }
        } catch (e) {
            results.push("middle-catch");
            if (!(e instanceof TypeError)) throw new Error("Should catch TypeError from innermost");
            catchExecuted = true;
            throw new ReferenceError("middle rethrow");
        } finally {
            results.push("middle-finally");
        }
    } catch (e) {
        results.push("outer-catch");
        if (!(e instanceof ReferenceError)) throw new Error("Should catch ReferenceError from middle");
    } finally {
        results.push("outer-finally");
        outerFinally = true;
    }

    if (results.length !== 7) throw new Error("All blocks should execute in order");
    if (results[0] !== "innermost-try") throw new Error("Innermost try should execute first");
    if (results[1] !== "innermost-catch") throw new Error("Innermost catch should execute second");
    if (results[2] !== "innermost-finally") throw new Error("Innermost finally should execute third");
    if (results[3] !== "middle-catch") throw new Error("Middle catch should execute fourth");
    if (results[4] !== "middle-finally") throw new Error("Middle finally should execute fifth");
    if (results[5] !== "outer-catch") throw new Error("Outer catch should execute sixth");
    if (results[6] !== "outer-finally") throw new Error("Outer finally should execute seventh");
    if (!outerFinally) throw new Error("Outer finally should execute");
    if (!innerFinally) throw new Error("Inner finally should execute");
    if (!catchExecuted) throw new Error("Middle catch should execute");
};
complexNestingTest();

// Test exception propagation through multiple finally blocks
var propagationTest = function() {
    var finallyBlocks = [];
    var exceptionCaught = false;

    try {
        try {
            try {
                throw new Error("propagation test");
            } finally {
                finallyBlocks.push("inner");
            }
        } finally {
            finallyBlocks.push("middle");
        }
    } catch (e) {
        exceptionCaught = true;
        if (e.message !== "propagation test") throw new Error("Original exception should propagate");
    } finally {
        finallyBlocks.push("outer");
    }

    if (finallyBlocks.length !== 3) throw new Error("All finally blocks should execute");
    if (finallyBlocks[0] !== "inner") throw new Error("Inner finally should execute first");
    if (finallyBlocks[1] !== "middle") throw new Error("Middle finally should execute second");
    if (finallyBlocks[2] !== "outer") throw new Error("Outer finally should execute last");
    if (!exceptionCaught) throw new Error("Exception should be caught after propagation");
};
propagationTest();

// Test finally block overriding exceptions
var finallyOverrideTest = function() {
    var finallyExecuted = false;
    var correctExceptionCaught = false;

    try {
        try {
            throw new Error("original exception");
        } finally {
            finallyExecuted = true;
            throw new TypeError("finally override");
        }
    } catch (e) {
        if (e instanceof TypeError && e.message === "finally override") {
            correctExceptionCaught = true;
        }
    }

    if (!finallyExecuted) throw new Error("Finally should execute");
    if (!correctExceptionCaught) throw new Error("Finally exception should override original");
};
finallyOverrideTest();

// Test finally block overriding return values
var finallyReturnOverrideTest = function() {
    function testFunction() {
        try {
            return "try return";
        } finally {
            return "finally return";
        }
    }

    var result = testFunction();
    if (result !== "finally return") throw new Error("Finally return should override try return");

    function testFunction2() {
        try {
            throw new Error("exception");
        } catch (e) {
            return "catch return";
        } finally {
            return "finally override";
        }
    }

    var result2 = testFunction2();
    if (result2 !== "finally override") throw new Error("Finally return should override catch return");
};
finallyReturnOverrideTest();

// Test resource cleanup patterns
var resourceCleanupTest = function() {
    var Resource = function(name) {
        this.name = name;
        this.isOpen = true;
        this.operations = [];
    };

    Resource.prototype.operation = function(op) {
        if (!this.isOpen) throw new Error("Resource is closed");
        this.operations.push(op);
    };

    Resource.prototype.close = function() {
        this.isOpen = false;
    };

    // Test successful cleanup
    var resource1 = new Resource("test1");
    var success = false;
    try {
        resource1.operation("op1");
        resource1.operation("op2");
        success = true;
    } finally {
        resource1.close();
    }

    if (!success) throw new Error("Operations should succeed");
    if (resource1.isOpen) throw new Error("Resource should be closed in finally");
    if (resource1.operations.length !== 2) throw new Error("Operations should be recorded");

    // Test cleanup with exception
    var resource2 = new Resource("test2");
    var exceptionHandled = false;
    try {
        try {
            resource2.operation("op1");
            throw new Error("operation failed");
        } finally {
            resource2.close();
        }
    } catch (e) {
        exceptionHandled = true;
    }

    if (!exceptionHandled) throw new Error("Exception should be handled");
    if (resource2.isOpen) throw new Error("Resource should be closed even with exception");
    if (resource2.operations.length !== 1) throw new Error("Operations before exception should be recorded");
};
resourceCleanupTest();

// Test exception chaining and cause tracking
var exceptionChainingTest = function() {
    function createChainedError(original, message) {
        var error = new Error(message);
        error.cause = original;
        return error;
    }

    var originalError = new TypeError("original type error");
    var wrappedError = createChainedError(originalError, "wrapped error");
    var chainedError = createChainedError(wrappedError, "final error");

    try {
        throw chainedError;
    } catch (e) {
        if (e.message !== "final error") throw new Error("Should catch final error");
        if (!e.cause) throw new Error("Error should have cause");
        if (e.cause.message !== "wrapped error") throw new Error("Cause should be wrapped error");
        if (!e.cause.cause) throw new Error("Wrapped error should have cause");
        if (!(e.cause.cause instanceof TypeError)) throw new Error("Original error should be TypeError");
    }
};
exceptionChainingTest();

// Test multiple catch blocks simulation (since JS doesn't have multiple catch)
var multipleCatchSimulation = function() {
    function handleError(error) {
        if (error instanceof TypeError) {
            return "handled TypeError: " + error.message;
        } else if (error instanceof ReferenceError) {
            return "handled ReferenceError: " + error.message;
        } else if (error instanceof Error) {
            return "handled generic Error: " + error.message;
        } else {
            return "handled unknown: " + String(error);
        }
    }

    var errors = [
        new TypeError("type error"),
        new ReferenceError("reference error"),
        new SyntaxError("syntax error"),
        "string error",
        42,
        null
    ];

    var results = [];
    for (var i = 0; i < errors.length; i++) {
        try {
            throw errors[i];
        } catch (e) {
            results.push(handleError(e));
        }
    }

    if (results[0] !== "handled TypeError: type error") throw new Error("TypeError not handled correctly");
    if (results[1] !== "handled ReferenceError: reference error") throw new Error("ReferenceError not handled correctly");
    if (results[2] !== "handled generic Error: syntax error") throw new Error("SyntaxError not handled correctly");
    if (results[3] !== "handled unknown: string error") throw new Error("String error not handled correctly");
    if (results[4] !== "handled unknown: 42") throw new Error("Number error not handled correctly");
    if (results[5] !== "handled unknown: null") throw new Error("Null error not handled correctly");
};
multipleCatchSimulation();

// Test async-like error handling patterns
var asyncErrorPatternTest = function() {
    function AsyncOperation(shouldFail) {
        this.shouldFail = shouldFail;
        this.callbacks = [];
    }

    AsyncOperation.prototype.then = function(callback) {
        this.callbacks.push(callback);
        return this;
    };

    AsyncOperation.prototype.catch = function(errorCallback) {
        this.errorCallback = errorCallback;
        return this;
    };

    AsyncOperation.prototype.execute = function() {
        try {
            if (this.shouldFail) {
                throw new Error("async operation failed");
            }
            for (var i = 0; i < this.callbacks.length; i++) {
                this.callbacks[i]("success");
            }
        } catch (e) {
            if (this.errorCallback) {
                this.errorCallback(e);
            } else {
                throw e;
            }
        }
    };

    var successResult = null;
    var errorResult = null;

    var op1 = new AsyncOperation(false);
    op1.then(function(result) {
        successResult = result;
    }).execute();

    if (successResult !== "success") throw new Error("Success callback should execute");

    var op2 = new AsyncOperation(true);
    op2.catch(function(error) {
        errorResult = error.message;
    }).execute();

    if (errorResult !== "async operation failed") throw new Error("Error callback should execute");
};
asyncErrorPatternTest();

// Test exception handling in generators (if supported)
var generatorErrorTest = function() {
    try {
        function* errorGenerator() {
            try {
                yield 1;
                throw new Error("generator error");
            } catch (e) {
                yield "caught: " + e.message;
            } finally {
                yield "finally block";
            }
        }

        var gen = errorGenerator();
        var values = [];
        var result;

        while (!(result = gen.next()).done) {
            values.push(result.value);
        }

        if (values.length !== 3) throw new Error("Generator should yield 3 values");
        if (values[0] !== 1) throw new Error("First yield should be 1");
        if (values[1] !== "caught: generator error") throw new Error("Catch block should yield");
        if (values[2] !== "finally block") throw new Error("Finally block should yield");
    } catch (e) {
        // Generator syntax might not be supported, skip test
        if (e.message.indexOf("Unexpected token") === -1 &&
            e.message.indexOf("syntax") === -1 &&
            e.message.indexOf("SyntaxError") === -1) {
            throw e;
        }
    }
};
generatorErrorTest();

// Test custom error classes and inheritance
var customErrorTest = function() {
    function CustomError(message) {
        this.name = "CustomError";
        this.message = message;
        if (Error.captureStackTrace) {
            Error.captureStackTrace(this, CustomError);
        }
    }
    CustomError.prototype = Object.create(Error.prototype);
    CustomError.prototype.constructor = CustomError;

    function ValidationError(field, value) {
        CustomError.call(this, "Validation failed for " + field + ": " + value);
        this.name = "ValidationError";
        this.field = field;
        this.value = value;
    }
    ValidationError.prototype = Object.create(CustomError.prototype);
    ValidationError.prototype.constructor = ValidationError;

    try {
        throw new ValidationError("email", "invalid@");
    } catch (e) {
        if (!(e instanceof ValidationError)) throw new Error("Should catch ValidationError");
        if (!(e instanceof CustomError)) throw new Error("ValidationError should inherit from CustomError");
        if (!(e instanceof Error)) throw new Error("CustomError should inherit from Error");
        if (e.field !== "email") throw new Error("Custom property should be preserved");
        if (e.value !== "invalid@") throw new Error("Custom property should be preserved");
    }
};
customErrorTest();

// Test error rethrowing patterns
var rethrowPatternTest = function() {
    var attempts = 0;
    var maxAttempts = 3;
    var finalError = null;

    function unreliableOperation() {
        attempts++;
        if (attempts < maxAttempts) {
            throw new Error("Operation failed, attempt " + attempts);
        }
        return "success";
    }

    function retryOperation() {
        while (attempts < maxAttempts) {
            try {
                return unreliableOperation();
            } catch (e) {
                finalError = e;
                if (attempts >= maxAttempts) {
                    throw new Error("Max attempts reached. Last error: " + e.message);
                }
            }
        }
    }

    try {
        var result = retryOperation();
        if (result !== "success") throw new Error("Should eventually succeed");
    } catch (e) {
        throw new Error("Retry should succeed: " + e.message);
    }

    if (attempts !== maxAttempts) throw new Error("Should attempt maximum times");
    if (!finalError) throw new Error("Should capture final error");
};
rethrowPatternTest();

// Test exception handling with eval (controlled test)
var evalErrorTest = function() {
    var evalSupported = true;
    try {
        eval("1 + 1");
    } catch (e) {
        evalSupported = false;
    }

    if (evalSupported) {
        try {
            eval("throw new Error('eval error')");
            throw new Error("Eval should throw error");
        } catch (e) {
            if (e.message !== "eval error") throw new Error("Should catch eval error");
        }

        try {
            eval("invalid syntax @#$");
            throw new Error("Eval should throw syntax error");
        } catch (e) {
            if (!(e instanceof SyntaxError)) throw new Error("Should catch SyntaxError from eval");
        }
    }
};
evalErrorTest();

// Test finally block execution order with returns
var finallyOrderTest = function() {
    var executionOrder = [];

    function testFunction() {
        try {
            executionOrder.push("try-start");
            return "return-value";
        } catch (e) {
            executionOrder.push("catch");
        } finally {
            executionOrder.push("finally");
        }
        executionOrder.push("after-finally");
    }

    var result = testFunction();

    if (result !== "return-value") throw new Error("Return value should be preserved");
    if (executionOrder.length !== 2) throw new Error("Finally should execute before return");
    if (executionOrder[0] !== "try-start") throw new Error("Try should execute first");
    if (executionOrder[1] !== "finally") throw new Error("Finally should execute second");
};
finallyOrderTest();

// Test exception handling in strict mode context
var strictModeErrorTest = function() {
    var strictError = null;

    try {
        (function() {
            "use strict";
            try {
                nonExistentVariable = "value";
            } catch (e) {
                strictError = e;
            }
        })();
    } catch (e) {
        // Fallback if strict mode isn't supported
        strictError = new ReferenceError("nonExistentVariable is not defined");
    }

    if (!strictError) throw new Error("Strict mode should throw ReferenceError");
    if (!(strictError instanceof ReferenceError)) throw new Error("Should be ReferenceError");
};
strictModeErrorTest();

// Test memory cleanup in exception scenarios
var memoryCleanupTest = function() {
    var allocations = [];
    var cleanedUp = 0;

    function Resource(size) {
        this.data = new Array(size);
        this.id = allocations.length;
        allocations.push(this);
    }

    Resource.prototype.cleanup = function() {
        this.data = null;
        cleanedUp++;
    };

    try {
        var resources = [];
        for (var i = 0; i < 5; i++) {
            resources.push(new Resource(100));
        }

        try {
            throw new Error("cleanup test");
        } finally {
            for (var j = 0; j < resources.length; j++) {
                resources[j].cleanup();
            }
        }
    } catch (e) {
        // Exception handled
    }

    if (cleanedUp !== 5) throw new Error("All resources should be cleaned up");
    if (allocations.length !== 5) throw new Error("All allocations should be tracked");
};
memoryCleanupTest();

// Test exception handling with closures
var closureErrorTest = function() {
    function createErrorHandler(prefix) {
        var errorCount = 0;

        return function(operation) {
            try {
                return operation();
            } catch (e) {
                errorCount++;
                throw new Error(prefix + " Error #" + errorCount + ": " + e.message);
            }
        };
    }

    var handler1 = createErrorHandler("Handler1");
    var handler2 = createErrorHandler("Handler2");

    try {
        handler1(function() {
            throw new Error("first error");
        });
    } catch (e) {
        if (e.message !== "Handler1 Error #1: first error") throw new Error("Handler1 should wrap error correctly");
    }

    try {
        handler1(function() {
            throw new Error("second error");
        });
    } catch (e) {
        if (e.message !== "Handler1 Error #2: second error") throw new Error("Handler1 should increment counter");
    }

    try {
        handler2(function() {
            throw new Error("different handler");
        });
    } catch (e) {
        if (e.message !== "Handler2 Error #1: different handler") throw new Error("Handler2 should have separate counter");
    }
};
closureErrorTest();

// Test nested exception types and error bubbling
var nestedExceptionTypesTest = function() {
    function Level1Error(message) {
        this.name = "Level1Error";
        this.message = message;
        this.level = 1;
    }
    Level1Error.prototype = Object.create(Error.prototype);

    function Level2Error(message, cause) {
        this.name = "Level2Error";
        this.message = message;
        this.level = 2;
        this.cause = cause;
    }
    Level2Error.prototype = Object.create(Error.prototype);

    function Level3Error(message, cause) {
        this.name = "Level3Error";
        this.message = message;
        this.level = 3;
        this.cause = cause;
    }
    Level3Error.prototype = Object.create(Error.prototype);

    try {
        try {
            try {
                throw new Level1Error("base error");
            } catch (e) {
                throw new Level2Error("wrapped once", e);
            }
        } catch (e) {
            throw new Level3Error("wrapped twice", e);
        }
    } catch (e) {
        if (!(e instanceof Level3Error)) throw new Error("Should catch Level3Error");
        if (e.level !== 3) throw new Error("Error should have correct level");
        if (!e.cause || e.cause.level !== 2) throw new Error("Should have Level2 cause");
        if (!e.cause.cause || e.cause.cause.level !== 1) throw new Error("Should have Level1 root cause");
    }
};
nestedExceptionTypesTest();

// Test exception handling with prototype chain
var prototypeChainErrorTest = function() {
    var BaseError = function(message) {
        this.message = message;
        this.name = "BaseError";
    };
    BaseError.prototype = Object.create(Error.prototype);
    BaseError.prototype.getDetails = function() {
        return this.name + ": " + this.message;
    };

    var SpecificError = function(message, code) {
        BaseError.call(this, message);
        this.name = "SpecificError";
        this.code = code;
    };
    SpecificError.prototype = Object.create(BaseError.prototype);
    SpecificError.prototype.constructor = SpecificError;
    SpecificError.prototype.getDetails = function() {
        return this.name + " [" + this.code + "]: " + this.message;
    };

    try {
        throw new SpecificError("specific error message", "ERR001");
    } catch (e) {
        if (!(e instanceof SpecificError)) throw new Error("Should catch SpecificError");
        if (!(e instanceof BaseError)) throw new Error("Should be instance of BaseError");
        if (!(e instanceof Error)) throw new Error("Should be instance of Error");
        if (e.code !== "ERR001") throw new Error("Code should be preserved");
        if (e.getDetails() !== "SpecificError [ERR001]: specific error message") {
            throw new Error("Method override should work");
        }
    }
};
prototypeChainErrorTest();

// Test exception handling with JSON operations
var jsonErrorTest = function() {
    var jsonErrors = [];

    // Test JSON.parse errors
    var invalidJsonStrings = [
        '{"invalid": json}',
        '{invalid: "json"}',
        '{"unclosed": "string}',
        '{trailing: "comma",}',
        'undefined',
        'function() {}'
    ];

    for (var i = 0; i < invalidJsonStrings.length; i++) {
        try {
            JSON.parse(invalidJsonStrings[i]);
            jsonErrors.push("No error thrown for: " + invalidJsonStrings[i]);
        } catch (e) {
            if (!(e instanceof SyntaxError)) {
                jsonErrors.push("Wrong error type for: " + invalidJsonStrings[i]);
            }
        }
    }

    // Test JSON.stringify errors with circular references
    var circularObj = {};
    circularObj.self = circularObj;

    try {
        JSON.stringify(circularObj);
        jsonErrors.push("No error thrown for circular reference");
    } catch (e) {
        if (!(e instanceof TypeError)) {
            jsonErrors.push("Wrong error type for circular reference");
        }
    }

    if (jsonErrors.length > 0) {
        throw new Error("JSON error tests failed: " + jsonErrors.join(", "));
    }
};
jsonErrorTest();

// Test exception handling with array operations
var arrayErrorTest = function() {
    var errors = [];

    // Test array access errors
    var arr = [1, 2, 3];
    try {
        var length = arr.length;
        if (length !== 3) errors.push("Array length should be 3");

        // These operations typically don't throw in JavaScript
        var outOfBounds = arr[100];
        if (outOfBounds !== undefined) {
            // This might not be an error in JS, but we note it
        }
    } catch (e) {
        errors.push("Unexpected error in array access: " + e.message);
    }

    // Test array method errors
    try {
        [1, 2, 3].forEach(null);
        errors.push("forEach should throw with null callback");
    } catch (e) {
        if (!(e instanceof TypeError)) {
            errors.push("forEach should throw TypeError with null callback");
        }
    }

    try {
        Array.prototype.join.call(null);
        errors.push("join should throw when called on null");
    } catch (e) {
        if (!(e instanceof TypeError)) {
            errors.push("join should throw TypeError when called on null");
        }
    }

    if (errors.length > 0) {
        throw new Error("Array error tests failed: " + errors.join(", "));
    }
};
arrayErrorTest();

// Test exception handling with function operations
var functionErrorTest = function() {
    var errors = [];

    // Test function call errors
    try {
        var notAFunction = "string";
        notAFunction();
        errors.push("Should throw when calling non-function");
    } catch (e) {
        if (!(e instanceof TypeError)) {
            errors.push("Should throw TypeError when calling non-function");
        }
    }

    // Test function binding errors
    try {
        Function.prototype.call.call(null);
        errors.push("Should throw when calling Function.prototype.call on null");
    } catch (e) {
        if (!(e instanceof TypeError)) {
            errors.push("Should throw TypeError when calling Function.prototype.call on null");
        }
    }

    // Test constructor errors
    try {
        new String();  // This actually works
        new Number();  // This actually works
        new Boolean(); // This actually works
    } catch (e) {
        errors.push("Primitive constructors should work: " + e.message);
    }

    try {
        new "not a constructor"();
        errors.push("Should throw when using new with non-constructor");
    } catch (e) {
        if (!(e instanceof TypeError)) {
            errors.push("Should throw TypeError when using new with non-constructor");
        }
    }

    if (errors.length > 0) {
        throw new Error("Function error tests failed: " + errors.join(", "));
    }
};
functionErrorTest();

// Test exception handling in loop constructs
var loopErrorTest = function() {
    var results = [];

    // Test try-catch in for loop
    for (var i = 0; i < 5; i++) {
        try {
            if (i === 2) {
                throw new Error("loop error at " + i);
            }
            results.push("success-" + i);
        } catch (e) {
            results.push("error-" + i);
        }
    }

    if (results.length !== 5) throw new Error("All loop iterations should execute");
    if (results[0] !== "success-0") throw new Error("First iteration should succeed");
    if (results[2] !== "error-2") throw new Error("Third iteration should error");
    if (results[4] !== "success-4") throw new Error("Last iteration should succeed");

    // Test break/continue with try-catch
    var breakResults = [];
    for (var j = 0; j < 5; j++) {
        try {
            if (j === 1) {
                continue;
            }
            if (j === 3) {
                break;
            }
            breakResults.push(j);
        } catch (e) {
            breakResults.push("error-" + j);
        } finally {
            breakResults.push("finally-" + j);
        }
    }

    // Should have: 0, finally-0, finally-1, 2, finally-2, finally-3
    if (breakResults.length !== 6) throw new Error("Break/continue with finally should work correctly");
};
loopErrorTest();

// Test performance implications of exception handling
var performanceErrorTest = function() {
    var startTime = Date.now();
    var exceptionCount = 0;
    var normalCount = 0;

    // Test exception performance vs normal flow
    for (var i = 0; i < 1000; i++) {
        if (i % 100 === 0) {
            try {
                throw new Error("performance test");
            } catch (e) {
                exceptionCount++;
            }
        } else {
            normalCount++;
        }
    }

    var endTime = Date.now();
    var duration = endTime - startTime;

    if (exceptionCount !== 10) throw new Error("Should throw 10 exceptions");
    if (normalCount !== 990) throw new Error("Should have 990 normal executions");

    // Basic performance check - shouldn't take too long
    if (duration > 5000) {
        throw new Error("Exception handling performance test took too long: " + duration + "ms");
    }
};
performanceErrorTest();

// Test exception handling with object operations
var objectErrorTest = function() {
    var errors = [];

    // Test property access on null/undefined
    try {
        var result = null.property;
        errors.push("Should throw when accessing property on null");
    } catch (e) {
        if (!(e instanceof TypeError)) {
            errors.push("Should throw TypeError when accessing property on null");
        }
    }

    try {
        var result = undefined.property;
        errors.push("Should throw when accessing property on undefined");
    } catch (e) {
        if (!(e instanceof TypeError)) {
            errors.push("Should throw TypeError when accessing property on undefined");
        }
    }

    // Test defineProperty errors
    try {
        Object.defineProperty(null, "prop", {value: 1});
        errors.push("Should throw when defining property on null");
    } catch (e) {
        if (!(e instanceof TypeError)) {
            errors.push("Should throw TypeError when defining property on null");
        }
    }

    // Test seal/freeze errors
    var obj = {};
    Object.seal(obj);
    try {
        obj.newProp = "value";
        // In non-strict mode, this might silently fail
        if ("newProp" in obj) {
            errors.push("Should not be able to add property to sealed object");
        }
    } catch (e) {
        // In strict mode, this would throw
        if (!(e instanceof TypeError)) {
            errors.push("Should throw TypeError when adding property to sealed object");
        }
    }

    if (errors.length > 0) {
        throw new Error("Object error tests failed: " + errors.join(", "));
    }
};
objectErrorTest();

// Final verification that all tests completed
var testCount = 0;
var testNames = [
    "complexNestingTest", "propagationTest", "finallyOverrideTest", "finallyReturnOverrideTest",
    "resourceCleanupTest", "exceptionChainingTest", "multipleCatchSimulation", "asyncErrorPatternTest",
    "generatorErrorTest", "customErrorTest", "rethrowPatternTest", "evalErrorTest",
    "finallyOrderTest", "strictModeErrorTest", "memoryCleanupTest", "closureErrorTest",
    "nestedExceptionTypesTest", "prototypeChainErrorTest", "jsonErrorTest", "arrayErrorTest",
    "functionErrorTest", "loopErrorTest", "performanceErrorTest", "objectErrorTest"
];

testCount = testNames.length;
if (testCount < 20) throw new Error("Should have at least 20 comprehensive tests");

// All tests passed if we reach this point
var finalTestResult = {
    totalTests: testCount,
    status: "PASSED",
    message: "All advanced try-catch-finally tests completed successfully"
};

if (finalTestResult.status !== "PASSED") throw new Error("Test suite did not complete successfully");
if (finalTestResult.totalTests !== testCount) throw new Error("Test count mismatch");